Workbook

Sheet Roster
A1: Player_Name | B1: Team | C1: Flight_ID | D1: Full_HCP | E1: Tee_Box | F1: Player_Order
A2: Fercho | B2: Blue | C2: Flight_1 | D2: 15 | E2: Ventaja Blanca | F2: 1
A3: Gaitan | B3: Blue | C3: Flight_1 | D3: 20 | E3: Ventaja Blanca | F3: 2
A4: Fito | B4: Red | C4: Flight_1 | D4: 11 | E4: Ventaja Blanca | F4: 3
A5: Adri Mejia | B5: Red | C5: Flight_1 | D5: 14 | E5: Ventaja Rojas | F5: 4
A6: Otto Fenwarth | B6: Blue | C6: Flight_2 | D6: 22 | E6: Ventaja Blanca | F6: 1
A7: Valenzuela | B7: Blue | C7: Flight_2 | D7: 11 | E7: Ventaja Blanca | F7: 2
A8: Cadavid | B8: Red | C8: Flight_2 | D8: 10 | E8: Ventaja Blanca | F8: 3
A9: Saenz | B9: Red | C9: Flight_2 | D9: 8 | E9: Ventaja Blanca | F9: 4
A10: Vargas | B10: Blue | C10: Flight_3 | D10: 14 | E10: Ventaja Blanca | F10: 1
A11: Mon | B11: Blue | C11: Flight_3 | D11: 19 | E11: Ventaja Blanca | F11: 2
A12: Berris | B12: Red | C12: Flight_3 | D12: 12 | E12: Ventaja Blanca | F12: 3
A13: Pablo Rueda | B13: Red | C13: Flight_3 | D13: 18 | E13: Ventaja Blanca | F13: 4
... A33: Camacho | B33: Red | C33: Flight_8 | D33: 13 | E33: Ventaja Blanca | F33: 4

Sheet Course
A1: Hole | B1: Par | C1: Hole_HCP_Index | D1: Ventaja Azul | E1: Ventaja Blanca | F1: Ventaja Rojas | G1: Ventaja Mixta | H1: Hole_1_9 | I1: Hole_10_18 | J1: Hole_Image | K1: Hole_Image_Red
A2: 1 | B2: 4 | C2: 3 | D2: 3 | E2: 3 | F2: 3 | G2: 3 | H2: 1 | I2: 10 | J2: https://storage.googleapis.com/glide-prod.appspot.com/uploads-v2/i8A0lNzzsZLQ68w3K8X6/pub/f8hD0k3v47Xnhg0gJI54.svg | K2: https://storage.googleapis.com/glide-prod.appspot.com/uploads-v2/i8A0lNzzsZLQ68w3K8X6/pub/M9kXOgQ7LzogO5SJoFLF.svg
A3: 2 | B3: 5 | C3: 9 | D3: 9 | E3: 9 | F3: 9 | G3: 9 | H3: 2 | I3: 11 | J3: https://storage.googleapis.com/glide-prod.appspot.com/uploads-v2/i8A0lNzzsZLQ68w3K8X6/pub/xSsRozFPLUn2lZ9MMJoh.svg | K3: https://storage.googleapis.com/glide-prod.appspot.com/uploads-v2/i8A0lNzzsZLQ68w3K8X6/pub/Jbt3Zujjw5ppM8rDK1Sv.svg
A4: 3 | B4: 4 | C4: 17 | D4: 17 | E4: 17 | F4: 17 | G4: 17 | H4: 3 | I4: 12 | J4: https://storage.googleapis.com/glide-prod.appspot.com/uploads-v2/i8A0lNzzsZLQ68w3K8X6/pub/lK0BFuqyL7YUlT6QULay.svg | K4: https://storage.googleapis.com/glide-prod.appspot.com/uploads-v2/i8A0lNzzsZLQ68w3K8X6/pub/jzUysXtjPRB9trTsZ0ql.svg
A5: 4 | B5: 4 | C5: 15 | D5: 15 | E5: 15 | F5: 11 | G5: 15 | H5: 4 | I5: 13 | J5: https://storage.googleapis.com/glide-prod.appspot.com/uploads-v2/i8A0lNzzsZLQ68w3K8X6/pub/8VCXJkjdjE38WVrhBodz.svg | K5: https://storage.googleapis.com/glide-prod.appspot.com/uploads-v2/i8A0lNzzsZLQ68w3K8X6/pub/4YG7hqx4n9vRbN1R69QM.svg
A6: 5 | B6: 3 | C6: 7 | D6: 7 | E6: 7 | F6: 5 | G6: 6 | H6: 5 | I6: 14 | J6: https://storage.googleapis.com/glide-prod.appspot.com/uploads-v2/i8A0lNzzsZLQ68w3K8X6/pub/ChulCLzux677x8akEqbp.svg | K6: https://storage.googleapis.com/glide-prod.appspot.com/uploads-v2/i8A0lNzzsZLQ68w3K8X6/pub/wlDDyss750IBhHmbQJHr.svg
A7: 6 | B7: 4 | C7: 5 | D7: 5 | E7: 5 | F7: 15 | G7: 10 | H7: 6 | I7: 15 | J7: https://storage.googleapis.com/glide-prod.appspot.com/uploads-v2/i8A0lNzzsZLQ68w3K8X6/pub/PeSpKAiLbKDkhbvv29sp.svg | K7: https://storage.googleapis.com/glide-prod.appspot.com/uploads-v2/i8A0lNzzsZLQ68w3K8X6/pub/3KrnbpsCnS77cKlypT8b.svg
A8: 7 | B8: 3 | C8: 13 | D8: 13 | E8: 13 | F8: 13 | G8: 13 | H8: 7 | I8: 16 | J8: https://storage.googleapis.com/glide-prod.appspot.com/uploads-v2/i8A0lNzzsZLQ68w3K8X6/pub/CR7yowrJrQq4bQw2k8Ql.svg | K8: https://storage.googleapis.com/glide-prod.appspot.com/uploads-v2/i8A0lNzzsZLQ68w3K8X6/pub/qLmZDgwPfBG9SapcEsQN.svg
A9: 8 | B9: 5 | C9: 11 | D9: 11 | E9: 11 | F9: 7 | G9: 7 | H9: 8 | I9: 17 | J9: https://storage.googleapis.com/glide-prod.appspot.com/uploads-v2/i8A0lNzzsZLQ68w3K8X6/pub/D3UstOHqjFAkirDq7NGM.svg | K9: https://storage.googleapis.com/glide-prod.appspot.com/uploads-v2/i8A0lNzzsZLQ68w3K8X6/pub/lIVrlUBCcswxvlJTTP3B.svg
A10: 9 | B10: 4 | C10: 1 | D10: 1 | E10: 1 | F10: 1 | G10: 1 | H10: 9 | I10: 18 | J10: https://storage.googleapis.com/glide-prod.appspot.com/uploads-v2/i8A0lNzzsZLQ68w3K8X6/pub/V9Z0FWr0rv0ShDU67XyR.svg | K10: https://storage.googleapis.com/glide-prod.appspot.com/uploads-v2/i8A0lNzzsZLQ68w3K8X6/pub/qUydupJtpoR1Yxq2K4cf.svg
A11: 10 | B11: 5 | C11: 10 | D11: 10 | E11: 10 | F11: 6 | G11: 8
A12: 11 | B12: 4 | C12: 2 | D12: 2 | E12: 2 | F12: 2 | G12: 2
A13: 12 | B13: 3 | C13: 4 | D13: 4 | E13: 4 | F13: 10 | G13: 4
A14: 13 | B14: 4 | C14: 6 | D14: 6 | E14: 6 | F14: 4 | G14: 5
A15: 14 | B15: 4 | C15: 16 | D15: 16 | E15: 16 | F15: 12 | G15: 16
A16: 15 | B16: 3 | C16: 18 | D16: 18 | E16: 18 | F16: 18 | G16: 18
A17: 16 | B17: 4 | C17: 14 | D17: 14 | E17: 14 | F17: 14 | G17: 14
A18: 17 | B18: 4 | C18: 8 | D18: 8 | E18: 8 | F18: 16 | G18: 12
A19: 18 | B19: 5 | C19: 12 | D19: 12 | E19: 12 | F19: 8 | G19: 11

Sheet Settings
A1: Setting_Name | B1: Value | C1: 🔒 Row ID
A2: HCP_Fourball_Individual | B2: 0.8 | C2: 3Cs9VFFQRIWi.UtnG48yPw
A3: HCP_Scramble_A_Player | B3: 0.6 | C3: ZWljtQxCT4KfOIeJWhCOHg
A4: HCP_Scramble_B_Player | B4: 0.4 | C4: 4SDk6-7jQaqaQlZTVQt5bQ

Sheet Awards
A1: Award | B1: Winner_Flight
A2: Longest Drive (Hole 10)
A3: Nearest to Pin (Hole 15)

Sheet Front9_Scores
A1: Flight_ID | B1: Player_Name | C1: Hole | D1: Gross_Score | E1: Player_Email
A2: Flight_7 | B2: Pocho | C2: 1 | D2: 4 | E2: philipp@hasskamp.de
A3: Flight_7 | B3: Phil | C3: 1 | D3: 5 | E3: philipp@hasskamp.de
A4: Flight_7 | B4: Velez | C4: 1 | D4: 5 | E4: philipp@hasskamp.de
A5: Flight_7 | B5: JP Mosquera | C5: 1 | D5: 5 | E5: philipp@hasskamp.de
A6: Flight_5 | B6: Sardi | C6: 1 | D6: 5 | E6: pulidostellabatti@gmail.com
A7: Flight_5 | B7: Pulido | C7: 1 | D7: 4 | E7: pulidostellabatti@gmail.com
A8: Flight_5 | B8: JC Casas | C8: 1 | D8: 6 | E8: pulidostellabatti@gmail.com
A9: Flight_5 | B9: Otoya | C9: 1 | D9: 4 | E9: pulidostellabatti@gmail.com
A10: Flight_7 | B10: Phil | C10: 2 | D10: 5 | E10: philipp@hasskamp.de
A11: Flight_7 | B11: Pocho | C11: 2 | D11: 5 | E11: philipp@hasskamp.de
A12: Flight_7 | B12: Velez | C12: 2 | D12: 5 | E12: philipp@hasskamp.de
A13: Flight_7 | B13: JP Mosquera | C13: 2 | D13: 5 | E13: philipp@hasskamp.de
... A52: Flight_3 | B52: Berris | C52: 1 | D52: 4 | E52: Pipe1188@hotmail.com
E53: simon.torres@gmail.com
A54: Flight_3 | B54: Pablo Rueda | C54: 1 | D54: 5 | E54: Pipe1188@hotmail.com
A55: Flight_5 | B55: Otoya | C55: 4 | D55: 5 | E55: pulidostellabatti@gmail.com
A56: Flight_5 | B56: Sardi | C56: 4 | D56: 4 | E56: pulidostellabatti@gmail.com
A57: Flight_5 | B57: JC Casas | C57: 4 | D57: 5 | E57: pulidostellabatti@gmail.com
A58: Flight_5 | B58: Pulido | C58: 4 | D58: 4 | E58: pulidostellabatti@gmail.com
A59: Flight_8 | B59: Veronica Perez | C59: 3 | D59: 4 | E59: Juanpablocamacho@hotmail.com
A60: Flight_8 | B60: Bernie | C60: 3 | D60: 5 | E60: Juanpablocamacho@hotmail.com
A61: Flight_8 | B61: Camacho | C61: 3 | D61: 4 | E61: Juanpablocamacho@hotmail.com
A62: Flight_8 | B62: Pilarica | C62: 3 | D62: 6 | E62: Juanpablocamacho@hotmail.com
A63: Flight_6 | B63: Schneider | C63: 1 | D63: 5 | E63: Christianscj@yahoo.com
A64: Flight_1 | B64: Fercho | C64: 3 | D64: 5 | E64: camilo.fer@gmail.com
E65: camilo.fer@gmail.com
A66: Flight_1 | B66: Gaitan | C66: 3 | D66: 5 | E66: camilo.fer@gmail.com
A67: Flight_1 | B67: Fito | C67: 3 | D67: 5 | E67: camilo.fer@gmail.com
A68: Flight_1 | B68: Adri Mejia | C68: 3 | D68: 4 | E68: camilo.fer@gmail.com
A69: Flight_7 | B69: Pocho | C69: 5 | D69: 4 | E69: philipp@hasskamp.de
A70: Flight_7 | B70: Phil | C70: 5 | D70: 4 | E70: philipp@hasskamp.de
A71: Flight_7 | B71: Velez | C71: 5 | D71: 4 | E71: philipp@hasskamp.de
A72: Flight_7 | B72: JP Mosquera | C72: 5 | D72: 3 | E72: philipp@hasskamp.de
A73: Flight_6 | B73: Garcia | C73: 1 | D73: 4 | E73: Christianscj@yahoo.com
A74: Flight_6 | B74: Pablo Acosta | C74: 1 | D74: 5 | E74: Christianscj@yahoo.com
A75: Flight_6 | B75: Ana Maria | C75: 1 | D75: 4 | E75: Christianscj@yahoo.com
A76: Flight_2 | B76: Saenz | C76: 2 | D76: 5 | E76: t_valenzuela17@yahoo.com.co
A77: Flight_2 | B77: Cadavid | C77: 2 | D77: 5 | E77: t_valenzuela17@yahoo.com.co
... A283: Flight_4 | B283: Esguerra | C283: 9 | D283: 4 | E283: Lucapfeifer@gmail.com

Sheet Back9_Scores
A1: Flight_ID | B1: Hole | C1: Red_Scramble_Score | D1: Blue_Scramble_Score | E1: Scramble_Key
A2: Flight_7 | B2: 10 | C2: 4 | E2: Flight_7 - 10 - Red
A3: Flight_7 | B3: 10 | D3: 3 | E3: Flight_7 - 10 - Blue
A4: Flight_5 | B4: 10 | C4: 5 | E4: Flight_5 - 10 - Red
A5: Flight_5 | B5: 10 | D5: 4 | E5: Flight_5 - 10 - Blue
A6: Flight_5 | B6: 11 | C6: 4 | E6: Flight_5 - 11 - Red
A7: Flight_5 | B7: 11 | D7: 4 | E7: Flight_5 - 11 - Blue
A8: Flight_7 | B8: 11 | C8: 4 | E8: Flight_7 - 11 - Red
A9: Flight_7 | B9: 11 | D9: 5 | E9: Flight_7 - 11 - Blue
A10: Flight_8 | B10: 10 | C10: 4 | E10: Flight_8 - 10 - Red
A11: Flight_8 | B11: 10 | D11: 5 | E11: Flight_8 - 10 - Blue
A12: Flight_7 | B12: 12 | D12: 3 | E12: Flight_7 - 12 - Blue
A13: Flight_7 | B13: 12 | C13: 4 | E13: Flight_7 - 12 - Red
A14: Flight_5 | B14: 12 | C14: 3 | E14: Flight_5 - 12 - Red
A15: Flight_5 | B15: 12 | D15: 3 | E15: Flight_5 - 12 - Blue
A16: Flight_1 | B16: 10 | C16: 4 | E16: Flight_1 - 10 - Red
A17: Flight_1 | B17: 10 | D17: 5 | E17: Flight_1 - 10 - Blue
A18: Flight_5 | B18: 13 | C18: 3 | E18: Flight_5 - 13 - Red
A19: Flight_5 | B19: 13 | D19: 3 | E19: Flight_5 - 13 - Blue
A20: Flight_7 | B20: 13 | C20: 5 | E20: Flight_7 - 13 - Red
A21: Flight_7 | B21: 13 | D21: 4 | E21: Flight_7 - 13 - Blue
A22: Flight_5 | B22: 14 | C22: 4 | E22: Flight_5 - 14 - Red
A23: Flight_5 | B23: 14 | D23: 4 | E23: Flight_5 - 14 - Blue
A24: Flight_5 | B24: 15 | C24: 3 | E24: Flight_5 - 15 - Red
A25: Flight_5 | B25: 15 | D25: 4 | E25: Flight_5 - 15 - Blue
A26: Flight_1 | B26: 11 | D26: 5 | E26: Flight_1 - 11 - Blue
A27: Flight_1 | B27: 11 | C27: 4 | E27: Flight_1 - 11 - Red
A28: Flight_3 | B28: 10 | C28: 5 | E28: Flight_3 - 10 - Red
A29: Flight_3 | B29: 10 | D29: 5 | E29: Flight_3 - 10 - Blue
A30: Flight_1 | B30: 12 | C30: 2 | E30: Flight_1 - 12 - Red
A31: Flight_1 | B31: 12 | D31: 3 | E31: Flight_1 - 12 - Blue
A32: Flight_2 | B32: 10 | D32: 5 | E32: Flight_2 - 10 - Blue
A33: Flight_2 | B33: 10 | C33: 5 | E33: Flight_2 - 10 - Red
A34: Flight_2 | B34: 11 | D34: 4 | E34: Flight_2 - 11 - Blue
A35: Flight_2 | B35: 11 | C35: 4 | E35: Flight_2 - 11 - Red
A36: Flight_7 | B36: 14 | C36: 4 | E36: Flight_7 - 14 - Red
A37: Flight_7 | B37: 14 | D37: 4 | E37: Flight_7 - 14 - Blue
A38: Flight_6 | B38: 10 | C38: 4 | E38: Flight_6 - 10 - Red
A39: Flight_3 | B39: 11 | C39: 5 | E39: Flight_3 - 11 - Red
A40: Flight_6 | B40: 10 | D40: 4 | E40: Flight_6 - 10 - Blue
...

Sheet Calc_Engine
A1: Flight_ID | B1: Player_Name | C1: Team | D1: Full_HCP | E1: Play_HCP_80pct | F1: Tee_Box | G1: Tee_Category | H1: Pair_Row | I1: Pair_ID | J1: Team | K1: HCP_A_Player | L1: HCP_B_Player | M1: Pair_Scramble_HCP | N1: Is_Mixed_Pair | Q1: RED TOTAL | R1: BLUE TOTAL
A2: =Roster!C2 -> Flight_1 | B2: =Roster!A2 -> Fercho | C2: =Roster!B2 -> Blue | D2: =Roster!D2 -> 15 | E2: =ROUND(D2*Settings!$B$2,0) -> 12 | F2: =Roster!E2 -> Ventaja Blanca | G2: Men | H2: 2 | I2: F1-Red | J2: Red | K2: =D4 -> 11 | L2: =D5 -> 14 | M2: =(K2+L2)*0.3 -> 7.5 | N2: =G4 <> G5 -> TRUE | Q2: =SUM(G216:G247) -> 21 | R2: =SUM(H216:H247) -> 19
A3: =Roster!C3 -> Flight_1 | B3: =Roster!A3 -> Gaitan | C3: =Roster!B3 -> Blue | D3: =Roster!D3 -> 20 | E3: =ROUND(D3*Settings!$B$2,0) -> 16 | F3: =Roster!E3 -> Ventaja Blanca | G3: Men | H3: 2 | I3: F1-Blue | J3: Blue | K3: =D2 -> 15 | L3: =D3 -> 20 | M3: =(K3+L3)*0.3 -> 10.5 | N3: =G2 <> G3 -> FALSE
A4: =Roster!C4 -> Flight_1 | B4: =Roster!A4 -> Fito | C4: =Roster!B4 -> Red | D4: =Roster!D4 -> 11 | E4: =ROUND(D4*Settings!$B$2,0) -> 9 | F4: =Roster!E4 -> Ventaja Blanca | G4: Men | H4: 4 | I4: F2-Red | J4: Red | K4: =D8 -> 10 | L4: =D9 -> 8 | M4: =(K4+L4)*0.3 -> 5.4 | N4: =G8 <> G9 -> FALSE
A5: =Roster!C5 -> Flight_1 | B5: =Roster!A5 -> Adri Mejia | C5: =Roster!B5 -> Red | D5: =Roster!D5 -> 14 | E5: =ROUND(D5*Settings!$B$2,0) -> 11 | F5: =Roster!E5 -> Ventaja Rojas | G5: Women | H5: 4 | I5: F2-Blue | J5: Blue | K5: =D6 -> 22 | L5: =D7 -> 11 | M5: =(K5+L5)*0.3 -> 9.9 | N5: =G6 <> G7 -> FALSE
A6: =Roster!C9 -> Flight_2 | B6: =Roster!A6 -> Otto Fenwarth | C6: =Roster!B6 -> Blue | D6: =Roster!D6 -> 22 | E6: =ROUND(D6*Settings!$B$2,0) -> 18 | F6: =Roster!E6 -> Ventaja Blanca | G6: Men | H6: 6 | I6: F3-Red | J6: Red | K6: =D12 -> 12 | L6: =D13 -> 18 | M6: =(K6+L6)*0.3 -> 9 | N6: =G12 <> G13 -> FALSE
A7: =Roster!C7 -> Flight_2 | B7: =Roster!A7 -> Valenzuela | C7: =Roster!B7 -> Blue | D7: =Roster!D7 -> 11 | E7: =ROUND(D7*Settings!$B$2,0) -> 9 | F7: =Roster!E7 -> Ventaja Blanca | G7: Men | H7: 6 | I7: F3-Blue | J7: Blue | K7: =D10 -> 14 | L7: =D11 -> 19 | M7: =(K7+L7)*0.3 -> 9.9 | N7: =G10 <> G11 -> FALSE
A8: =Roster!C8 -> Flight_2 | B8: =Roster!A8 -> Cadavid | C8: =Roster!B8 -> Red | D8: =Roster!D8 -> 10 | E8: =ROUND(D8*Settings!$B$2,0) -> 8 | F8: =Roster!E8 -> Ventaja Blanca | G8: Men | H8: 8 | I8: F4-Red | J8: Red | K8: =D16 -> 19 | L8: =D17 -> 10 | M8: =(K8+L8)*0.3 -> 8.7 | N8: =G16 <> G17 -> FALSE
A9: =Roster!C6 -> Flight_2 | B9: =Roster!A9 -> Saenz | C9: =Roster!B9 -> Red | D9: =Roster!D9 -> 8 | E9: =ROUND(D9*Settings!$B$2,0) -> 6 | F9: =Roster!E9 -> Ventaja Blanca | G9: Men | H9: 8 | I9: F4-Blue | J9: Blue | K9: =D14 -> 11 | L9: =D15 -> 27 | M9: =(K9+L9)*0.3 -> 11.4 | N9: =G14 <> G15 -> TRUE
A10: =Roster!C10 -> Flight_3 | B10: =Roster!A10 -> Vargas | C10: =Roster!B10 -> Blue | D10: =Roster!D10 -> 14 | E10: =ROUND(D10*Settings!$B$2,0) -> 11 | F10: =Roster!E10 -> Ventaja Blanca | G10: Men | H10: 10 | I10: F5-Red | J10: Red | K10: =D20 -> 5 | L10: =D21 -> 17 | M10: =(K10+L10)*0.3 -> 6.6 | N10: =G20 <> G21 -> TRUE
A11: =Roster!C11 -> Flight_3 | B11: =Roster!A11 -> Mon | C11: =Roster!B11 -> Blue | D11: =Roster!D11 -> 19 | E11: =ROUND(D11*Settings!$B$2,0) -> 15 | F11: =Roster!E11 -> Ventaja Blanca | G11: Men | H11: 10 | I11: F5-Blue | J11: Blue | K11: =D18 -> 16 | L11: =D19 -> 27 | M11: =(K11+L11)*0.3 -> 12.9 | N11: =G18 <> G19 -> FALSE
A12: =Roster!C12 -> Flight_3 | B12: =Roster!A12 -> Berris | C12: =Roster!B12 -> Red | D12: =Roster!D12 -> 12 | E12: =ROUND(D12*Settings!$B$2,0) -> 10 | F12: =Roster!E12 -> Ventaja Blanca | G12: Men | H12: 12 | I12: F6-Red | J12: Red | K12: =D24 -> 19 | L12: =D25 -> 1 | M12: =(K12+L12)*0.3 -> 6 | N12: =G24 <> G25 -> FALSE
A13: =Roster!C13 -> Flight_3 | B13: =Roster!A13 -> Pablo Rueda | C13: =Roster!B13 -> Red | D13: =Roster!D13 -> 18 | E13: =ROUND(D13*Settings!$B$2,0) -> 14 | F13: =Roster!E13 -> Ventaja Blanca | G13: Men | H13: 12 | I13: F6-Blue | J13: Blue | K13: =D22 -> 11 | L13: =D23 -> 6 | M13: =(K13+L13)*0.3 -> 5.1 | N13: =G22 <> G23 -> TRUE
A14: =Roster!C15 -> Flight_4 | B14: =Roster!A14 -> Luca | C14: =Roster!B14 -> Blue | D14: =Roster!D14 -> 11 | E14: =ROUND(D14*Settings!$B$2,0) -> 9 | F14: =Roster!E14 -> Ventaja Blanca | G14: Men | H14: 14 | I14: F7-Red | J14: Red | K14: =D28 -> 16 | L14: =D29 -> 16 | M14: =(K14+L14)*0.3 -> 9.6 | N14: =G28 <> G29 -> FALSE
A15: =Roster!C14 -> Flight_4 | B15: =Roster!A15 -> Rocha | C15: =Roster!B15 -> Blue | D15: =Roster!D15 -> 27 | E15: =ROUND(D15*Settings!$B$2,0) -> 22 | F15: =Roster!E15 -> Ventaja Rojas | G15: Women | H15: 14 | I15: F7-Blue | J15: Blue | K15: =D26 -> 6 | L15: =D27 -> 9 | M15: =(K15+L15)*0.3 -> 4.5 | N15: =G26 <> G27 -> FALSE
A16: =Roster!C17 -> Flight_4 | B16: =Roster!A16 -> Matiz | C16: =Roster!B16 -> Red | D16: =Roster!D16 -> 19 | E16: =ROUND(D16*Settings!$B$2,0) -> 15 | F16: =Roster!E16 -> Ventaja Blanca | G16: Men | H16: 16 | I16: F8-Red | J16: Red | K16: =D32 -> 11 | L16: =D33 -> 13 | M16: =(K16+L16)*0.3 -> 7.2 | N16: =G32 <> G33 -> TRUE
A17: =Roster!C16 -> Flight_4 | B17: =Roster!A17 -> Esguerra | C17: =Roster!B17 -> Red | D17: =Roster!D17 -> 10 | E17: =ROUND(D17*Settings!$B$2,0) -> 8 | F17: =Roster!E17 -> Ventaja Blanca | G17: Men | H17: 16 | I17: F8-Blue | J17: Blue | K17: =D30 -> 11 | L17: =D31 -> 18 | M17: =(K17+L17)*0.3 -> 8.7 | N17: =G30 <> G31 -> TRUE
A18: =Roster!C20 -> Flight_5 | B18: =Roster!A18 -> Sardi | C18: =Roster!B18 -> Blue | D18: =Roster!D18 -> 16 | E18: =ROUND(D18*Settings!$B$2,0) -> 13 | F18: =Roster!E18 -> Ventaja Blanca | G18: Men | H18: 3
A19: =Roster!C18 -> Flight_5 | B19: =Roster!A19 -> JC Casas | C19: =Roster!B19 -> Blue | D19: =Roster!D19 -> 27 | E19: =ROUND(D19*Settings!$B$2,0) -> 22 | F19: =Roster!E19 -> Ventaja Blanca | G19: Men | H19: 3
A20: =Roster!C21 -> Flight_5 | B20: =Roster!A20 -> Pulido | C20: =Roster!B20 -> Red | D20: =Roster!D20 -> 5 | E20: =ROUND(D20*Settings!$B$2,0) -> 4 | F20: =Roster!E20 -> Ventaja Blanca | G20: Men | H20: 5
A21: =Roster!C19 -> Flight_5 | B21: =Roster!A21 -> Otoya | C21: =Roster!B21 -> Red | D21: =Roster!D21 -> 17 | E21: =ROUND(D21*Settings!$B$2,0) -> 14 | F21: =Roster!E21 -> Ventaja Rojas | G21: Women | H21: 5
A22: =Roster!C22 -> Flight_6 | B22: =Roster!A22 -> Ana Maria | C22: =Roster!B22 -> Blue | D22: =Roster!D22 -> 11 | E22: =ROUND(D22*Settings!$B$2,0) -> 9 | F22: =Roster!E22 -> Ventaja Rojas | G22: Women | H22: 7
A23: =Roster!C23 -> Flight_6 | B23: =Roster!A23 -> Schneider | C23: =Roster!B23 -> Blue | D23: =Roster!D23 -> 6 | E23: =ROUND(D23*Settings!$B$2,0) -> 5 | F23: =Roster!E23 -> Ventaja Blanca | G23: Men | H23: 7
A24: =Roster!C25 -> Flight_6 | B24: =Roster!A24 -> Pablo Acosta | C24: =Roster!B24 -> Red | D24: =Roster!D24 -> 19 | E24: =ROUND(D24*Settings!$B$2,0) -> 15 | F24: =Roster!E24 -> Ventaja Blanca | G24: Men | H24: 9
A25: =Roster!C24 -> Flight_6 | B25: =Roster!A25 -> Garcia | C25: =Roster!B25 -> Red | D25: =Roster!D25 -> 1 | E25: =ROUND(D25*Settings!$B$2,0) -> 1 | F25: =Roster!E25 -> Ventaja Blanca | G25: Men | H25: 9
A26: =Roster!C26 -> Flight_7 | B26: =Roster!A26 -> Pocho | C26: =Roster!B26 -> Blue | D26: =Roster!D26 -> 6 | E26: =ROUND(D26*Settings!$B$2,0) -> 5 | F26: =Roster!E26 -> Ventaja Blanca | G26: Men | H26: 11
A27: =Roster!C28 -> Flight_7 | B27: =Roster!A27 -> Phil | C27: =Roster!B27 -> Blue | D27: =Roster!D27 -> 9 | E27: =ROUND(D27*Settings!$B$2,0) -> 7 | F27: =Roster!E27 -> Ventaja Blanca | G27: Men | H27: 11
A28: =Roster!C27 -> Flight_7 | B28: =Roster!A28 -> Velez | C28: =Roster!B28 -> Red | D28: =Roster!D28 -> 16 | E28: =ROUND(D28*Settings!$B$2,0) -> 13 | F28: =Roster!E28 -> Ventaja Blanca | G28: Men | H28: 13
A29: =Roster!C29 -> Flight_7 | B29: =Roster!A29 -> JP Mosquera | C29: =Roster!B29 -> Red | D29: =Roster!D29 -> 16 | E29: =ROUND(D29*Settings!$B$2,0) -> 13 | F29: =Roster!E29 -> Ventaja Blanca | G29: Men | H29: 13
A30: =Roster!C33 -> Flight_8 | B30: =Roster!A30 -> Veronica Perez | C30: =Roster!B30 -> Blue | D30: =Roster!D30 -> 11 | E30: =ROUND(D30*Settings!$B$2,0) -> 9 | F30: =Roster!E30 -> Ventaja Rojas | G30: Women | H30: 15
A31: =Roster!C31 -> Flight_8 | B31: =Roster!A31 -> Bernie | C31: =Roster!B31 -> Blue | D31: =Roster!D31 -> 18 | E31: =ROUND(D31*Settings!$B$2,0) -> 14 | F31: =Roster!E31 -> Ventaja Blanca | G31: Men | H31: 15
A32: =Roster!C32 -> Flight_8 | B32: =Roster!A32 -> Pilarica | C32: =Roster!B32 -> Red | D32: =Roster!D32 -> 11 | E32: =ROUND(D32*Settings!$B$2,0) -> 9 | F32: =Roster!E32 -> Ventaja Rojas | G32: Women | H32: 17
A33: =Roster!C30 -> Flight_8 | B33: =Roster!A33 -> Camacho | C33: =Roster!B33 -> Red | D33: =Roster!D33 -> 13 | E33: =ROUND(D33*Settings!$B$2,0) -> 10 | F33: =Roster!E33 -> Ventaja Blanca | G33: Men | H33: 17
A35: Match | B35: Hole | C35: P1-Red-Gross | D35: P1-Red-Strokes_IND | E35: P1-Red-Net_IND | F35: P1-Red-Strokes_FB | G35: P1-Red-Net_FB | H35: P2-Red-Gross | I35: P2-Red-Strokes_IND | J35: P2-Red-Net_IND | K35: P2-Red-Strokes_FB | L35: P2-Red-Net_FB | M35: P1-Blue-Gross | N35: P1-Blue-Strokes_IND | O35: P1-Blue-Net_IND | P35: P1-Blue-Strokes_FB | Q35: P1-Blue-Net_FB | R35: P2-Blue-Gross | S35: P2-Blue-Strokes_IND | T35: P2-Blue-Net_IND | U35: P2-Blue-Strokes_FB | V35: P2-Blue-Net_FB | W35: FB-Winner | X35: I1-Winner | Y35: I2-Winner | Z35: Flight_ID | AA35: P1_Red_Row | AB35: P2_Red_Row | AC35: P1_Blue_Row | AD35: P2_Blue_Row
A36: Flight_1 | B36: 1 | C36: {=SUMIFS(Front9_Scores!$D:$D, Front9_Scores!$A:$A, $A36, Front9_Scores!$B:$B, INDEX($B:$B,$AA36), Front9_Scores!$C:$C, $B36)} -> 6 | D36: {=LET(player_hcp,INDEX($E:$E,$AA36),player_tee,INDEX($F:$F,$AA36),current_hole,$B36,hole_hcp_index,XLOOKUP(current_hole,Course!$A:$A,XLOOKUP(player_tee,Course!$D$1:$F$1,Course!$D:$F)),IF(player_hcp>=hole_hcp_index,1,0)+IF(player_hcp>=(18+hole_hcp_index),1,0))} -> 1 | E36: =IF($C36=0,"",$C36-D36) -> 5 | F36: {=LET( player_row, $AA36, player_hcp, INDEX($E:$E, player_row), player_flight, INDEX($A:$A, player_row), player_team, INDEX($C:$C, player_row), current_hole, $B36, flight_number, VALUE(RIGHT(player_flight, LEN(player_flight) - 7)), pair_id, "F" & flight_number & "-" & player_team, pair_row, MATCH(pair_id, $I:$I, 0), is_mixed, INDEX($N:$N, pair_row), mixed_hcp_index, VLOOKUP(current_hole, Course!$A:$G, 7, FALSE), default_hcp_index, VLOOKUP(current_hole, Course!$A:$G, 3, FALSE), hole_hcp_index_to_use, IF(is_mixed, mixed_hcp_index, default_hcp_index), strokes, IF(player_hcp>=hole_hcp_index_to_use, 1, 0) + IF(player_hcp>=(18+hole_hcp_index_to_use), 1, 0), strokes )} -> 1 | G36: =IF($C36=0,"",$C36-F36) -> 5 | H36: {=SUMIFS(Front9_Scores!$D:$D, Front9_Scores!$A:$A, $A36, Front9_Scores!$B:$B, INDEX($B:$B,$AB36), Front9_Scores!$C:$C, $B36)} -> 7 | I36: {=LET(player_hcp,INDEX($E:$E,$AB36),player_tee,INDEX($F:$F,$AB36),current_hole,$B36,hole_hcp_index,XLOOKUP(current_hole,Course!$A:$A,XLOOKUP(player_tee,Course!$D$1:$F$1,Course!$D:$F)),IF(player_hcp>=hole_hcp_index,1,0)+IF(player_hcp>=(18+hole_hcp_index),1,0))} -> 1 | J36: =IF($H36=0,"",$H36-I36) -> 6 | K36: {=LET( player_row, $AB36, player_hcp, INDEX($E:$E, player_row), player_flight, INDEX($A:$A, player_row), player_team, INDEX($C:$C, player_row), current_hole, $B36, flight_number, VALUE(RIGHT(player_flight, LEN(player_flight) - 7)), pair_id, "F" & flight_number & "-" & player_team, pair_row, MATCH(pair_id, $I:$I, 0), is_mixed, INDEX($N:$N, pair_row), mixed_hcp_index, VLOOKUP(current_hole, Course!$A:$G, 7, FALSE), default_hcp_index, VLOOKUP(current_hole, Course!$A:$G, 3, FALSE), hole_hcp_index_to_use, IF(is_mixed, mixed_hcp_index, default_hcp_index), strokes, IF(player_hcp>=hole_hcp_index_to_use, 1, 0) + IF(player_hcp>=(18+hole_hcp_index_to_use), 1, 0), strokes )} -> 1 | L36: =IF($H36=0,"",$H36-K36) -> 6 | M36: {=SUMIFS(Front9_Scores!$D:$D, Front9_Scores!$A:$A, $A36, Front9_Scores!$B:$B, INDEX($B:$B,$AC36), Front9_Scores!$C:$C, $B36)} -> 5 | N36: {=LET(player_hcp,INDEX($E:$E,$AC36),player_tee,INDEX($F:$F,$AC36),current_hole,$B36,hole_hcp_index,XLOOKUP(current_hole,Course!$A:$A,XLOOKUP(player_tee,Course!$D$1:$F$1,Course!$D:$F)),IF(player_hcp>=hole_hcp_index,1,0)+IF(player_hcp>=(18+hole_hcp_index),1,0))} -> 1 | O36: =IF(M36=0,"",M36-N36) -> 4 | P36: {=LET( player_row, $AC36, player_hcp, INDEX($E:$E, player_row), player_flight, INDEX($A:$A, player_row), player_team, INDEX($C:$C, player_row), current_hole, $B36, flight_number, VALUE(RIGHT(player_flight, LEN(player_flight) - 7)), pair_id, "F" & flight_number & "-" & player_team, pair_row, MATCH(pair_id, $I:$I, 0), is_mixed, INDEX($N:$N, pair_row), mixed_hcp_index, VLOOKUP(current_hole, Course!$A:$G, 7, FALSE), default_hcp_index, VLOOKUP(current_hole, Course!$A:$G, 3, FALSE), hole_hcp_index_to_use, IF(is_mixed, mixed_hcp_index, default_hcp_index), strokes, IF(player_hcp>=hole_hcp_index_to_use, 1, 0) + IF(player_hcp>=(18+hole_hcp_index_to_use), 1, 0), strokes )} -> 1 | Q36: =IF($M36=0,"",$M36-P36) -> 4 | R36: {=SUMIFS(Front9_Scores!$D:$D, Front9_Scores!$A:$A, $A36, Front9_Scores!$B:$B, INDEX($B:$B,$AD36), Front9_Scores!$C:$C, $B36)} -> 5 | S36: {=LET(player_hcp,INDEX($E:$E,$AD36),player_tee,INDEX($F:$F,$AD36),current_hole,$B36,hole_hcp_index,XLOOKUP(current_hole,Course!$A:$A,XLOOKUP(player_tee,Course!$D$1:$F$1,Course!$D:$F)),IF(player_hcp>=hole_hcp_index,1,0)+IF(player_hcp>=(18+hole_hcp_index),1,0))} -> 1 | T36: =IF(R36=0,"",R36-S36) -> 4 | U36: {=LET( player_row, $AD36, player_hcp, INDEX($E:$E, player_row), player_flight, INDEX($A:$A, player_row), player_team, INDEX($C:$C, player_row), current_hole, $B36, flight_number, VALUE(RIGHT(player_flight, LEN(player_flight) - 7)), pair_id, "F" & flight_number & "-" & player_team, pair_row, MATCH(pair_id, $I:$I, 0), is_mixed, INDEX($N:$N, pair_row), mixed_hcp_index, VLOOKUP(current_hole, Course!$A:$G, 7, FALSE), default_hcp_index, VLOOKUP(current_hole, Course!$A:$G, 3, FALSE), hole_hcp_index_to_use, IF(is_mixed, mixed_hcp_index, default_hcp_index), strokes, IF(player_hcp>=hole_hcp_index_to_use, 1, 0) + IF(player_hcp>=(18+hole_hcp_index_to_use), 1, 0), strokes )} -> 1 | V36: =IF($R36=0,"",$R36-U36) -> 4 | W36: =IF(COUNT(G36,L36,Q36,V36)<4,"",LET(Red_Best_Ball,MIN(G36,L36),Blue_Best_Ball,MIN(Q36,V36),IF(Red_Best_Ball<Blue_Best_Ball,"Red",IF(Blue_Best_Ball<Red_Best_Ball,"Blue","Tie")))) -> Blue | X36: =IF(COUNT(E36,O36)<2,"",IF(E36<O36,"Red",IF(O36<E36,"Blue","Tie"))) -> Blue | Y36: =IF(COUNT(J36,T36)<2,"",IF(J36<T36,"Red",IF(T36<J36,"Blue","Tie"))) -> Blue | Z36: =A36 -> Flight_1 | AA36: 4 | AB36: 5 | AC36: 2 | AD36: 3
A37: Flight_1 | B37: 2 | C37: {=SUMIFS(Front9_Scores!$D:$D, Front9_Scores!$A:$A, $A37, Front9_Scores!$B:$B, INDEX($B:$B,$AA37), Front9_Scores!$C:$C, $B37)} -> 5 | D37: {=LET(player_hcp,INDEX($E:$E,$AA37),player_tee,INDEX($F:$F,$AA37),current_hole,$B37,hole_hcp_index,XLOOKUP(current_hole,Course!$A:$A,XLOOKUP(player_tee,Course!$D$1:$F$1,Course!$D:$F)),IF(player_hcp>=hole_hcp_index,1,0)+IF(player_hcp>=(18+hole_hcp_index),1,0))} -> 1 | E37: =IF($C37=0,"",$C37-D37) -> 4 | F37: {=LET( player_row, $AA37, player_hcp, INDEX($E:$E, player_row), player_flight, INDEX($A:$A, player_row), player_team, INDEX($C:$C, player_row), current_hole, $B37, flight_number, VALUE(RIGHT(player_flight, LEN(player_flight) - 7)), pair_id, "F" & flight_number & "-" & player_team, pair_row, MATCH(pair_id, $I:$I, 0), is_mixed, INDEX($N:$N, pair_row), mixed_hcp_index, VLOOKUP(current_hole, Course!$A:$G, 7, FALSE), default_hcp_index, VLOOKUP(current_hole, Course!$A:$G, 3, FALSE), hole_hcp_index_to_use, IF(is_mixed, mixed_hcp_index, default_hcp_index), strokes, IF(player_hcp>=hole_hcp_index_to_use, 1, 0) + IF(player_hcp>=(18+hole_hcp_index_to_use), 1, 0), strokes )} -> 1 | G37: =IF($C37=0,"",$C37-F37) -> 4 | H37: {=SUMIFS(Front9_Scores!$D:$D, Front9_Scores!$A:$A, $A37, Front9_Scores!$B:$B, INDEX($B:$B,$AB37), Front9_Scores!$C:$C, $B37)} -> 6 | I37: {=LET(player_hcp,INDEX($E:$E,$AB37),player_tee,INDEX($F:$F,$AB37),current_hole,$B37,hole_hcp_index,XLOOKUP(current_hole,Course!$A:$A,XLOOKUP(player_tee,Course!$D$1:$F$1,Course!$D:$F)),IF(player_hcp>=hole_hcp_index,1,0)+IF(player_hcp>=(18+hole_hcp_index),1,0))} -> 1 | J37: =IF($H37=0,"",$H37-I37) -> 5 | K37: {=LET( player_row, $AB37, player_hcp, INDEX($E:$E, player_row), player_flight, INDEX($A:$A, player_row), player_team, INDEX($C:$C, player_row), current_hole, $B37, flight_number, VALUE(RIGHT(player_flight, LEN(player_flight) - 7)), pair_id, "F" & flight_number & "-" & player_team, pair_row, MATCH(pair_id, $I:$I, 0), is_mixed, INDEX($N:$N, pair_row), mixed_hcp_index, VLOOKUP(current_hole, Course!$A:$G, 7, FALSE), default_hcp_index, VLOOKUP(current_hole, Course!$A:$G, 3, FALSE), hole_hcp_index_to_use, IF(is_mixed, mixed_hcp_index, default_hcp_index), strokes, IF(player_hcp>=hole_hcp_index_to_use, 1, 0) + IF(player_hcp>=(18+hole_hcp_index_to_use), 1, 0), strokes )} -> 1 | L37: =IF($H37=0,"",$H37-K37) -> 5 | M37: {=SUMIFS(Front9_Scores!$D:$D, Front9_Scores!$A:$A, $A37, Front9_Scores!$B:$B, INDEX($B:$B,$AC37), Front9_Scores!$C:$C, $B37)} -> 6 | N37: {=LET(player_hcp,INDEX($E:$E,$AC37),player_tee,INDEX($F:$F,$AC37),current_hole,$B37,hole_hcp_index,XLOOKUP(current_hole,Course!$A:$A,XLOOKUP(player_tee,Course!$D$1:$F$1,Course!$D:$F)),IF(player_hcp>=hole_hcp_index,1,0)+IF(player_hcp>=(18+hole_hcp_index),1,0))} -> 1 | O37: =IF(M37=0,"",M37-N37) -> 5 | P37: {=LET( player_row, $AC37, player_hcp, INDEX($E:$E, player_row), player_flight, INDEX($A:$A, player_row), player_team, INDEX($C:$C, player_row), current_hole, $B37, flight_number, VALUE(RIGHT(player_flight, LEN(player_flight) - 7)), pair_id, "F" & flight_number & "-" & player_team, pair_row, MATCH(pair_id, $I:$I, 0), is_mixed, INDEX($N:$N, pair_row), mixed_hcp_index, VLOOKUP(current_hole, Course!$A:$G, 7, FALSE), default_hcp_index, VLOOKUP(current_hole, Course!$A:$G, 3, FALSE), hole_hcp_index_to_use, IF(is_mixed, mixed_hcp_index, default_hcp_index), strokes, IF(player_hcp>=hole_hcp_index_to_use, 1, 0) + IF(player_hcp>=(18+hole_hcp_index_to_use), 1, 0), strokes )} -> 1 | Q37: =IF($M37=0,"",$M37-P37) -> 5 | R37: {=SUMIFS(Front9_Scores!$D:$D, Front9_Scores!$A:$A, $A37, Front9_Scores!$B:$B, INDEX($B:$B,$AD37), Front9_Scores!$C:$C, $B37)} -> 6 | S37: {=LET(player_hcp,INDEX($E:$E,$AD37),player_tee,INDEX($F:$F,$AD37),current_hole,$B37,hole_hcp_index,XLOOKUP(current_hole,Course!$A:$A,XLOOKUP(player_tee,Course!$D$1:$F$1,Course!$D:$F)),IF(player_hcp>=hole_hcp_index,1,0)+IF(player_hcp>=(18+hole_hcp_index),1,0))} -> 1 | T37: =IF(R37=0,"",R37-S37) -> 5 | U37: {=LET( player_row, $AD37, player_hcp, INDEX($E:$E, player_row), player_flight, INDEX($A:$A, player_row), player_team, INDEX($C:$C, player_row), current_hole, $B37, flight_number, VALUE(RIGHT(player_flight, LEN(player_flight) - 7)), pair_id, "F" & flight_number & "-" & player_team, pair_row, MATCH(pair_id, $I:$I, 0), is_mixed, INDEX($N:$N, pair_row), mixed_hcp_index, VLOOKUP(current_hole, Course!$A:$G, 7, FALSE), default_hcp_index, VLOOKUP(current_hole, Course!$A:$G, 3, FALSE), hole_hcp_index_to_use, IF(is_mixed, mixed_hcp_index, default_hcp_index), strokes, IF(player_hcp>=hole_hcp_index_to_use, 1, 0) + IF(player_hcp>=(18+hole_hcp_index_to_use), 1, 0), strokes )} -> 1 | V37: =IF($R37=0,"",$R37-U37) -> 5 | W37: =IF(COUNT(G37,L37,Q37,V37)<4,"",LET(Red_Best_Ball,MIN(G37,L37),Blue_Best_Ball,MIN(Q37,V37),IF(Red_Best_Ball<Blue_Best_Ball,"Red",IF(Blue_Best_Ball<Red_Best_Ball,"Blue","Tie")))) -> Red | X37: =IF(COUNT(E37,O37)<2,"",IF(E37<O37,"Red",IF(O37<E37,"Blue","Tie"))) -> Red | Y37: =IF(COUNT(J37,T37)<2,"",IF(J37<T37,"Red",IF(T37<J37,"Blue","Tie"))) -> Tie | Z37: =A37 -> Flight_1 | AA37: 4 | AB37: 5 | AC37: 2 | AD37: 3
A38: Flight_1 | B38: 3 | C38: {=SUMIFS(Front9_Scores!$D:$D, Front9_Scores!$A:$A, $A38, Front9_Scores!$B:$B, INDEX($B:$B,$AA38), Front9_Scores!$C:$C, $B38)} -> 5 | D38: {=LET(player_hcp,INDEX($E:$E,$AA38),player_tee,INDEX($F:$F,$AA38),current_hole,$B38,hole_hcp_index,XLOOKUP(current_hole,Course!$A:$A,XLOOKUP(player_tee,Course!$D$1:$F$1,Course!$D:$F)),IF(player_hcp>=hole_hcp_index,1,0)+IF(player_hcp>=(18+hole_hcp_index),1,0))} -> 0 | E38: =IF($C38=0,"",$C38-D38) -> 5 | F38: {=LET( player_row, $AA38, player_hcp, INDEX($E:$E, player_row), player_flight, INDEX($A:$A, player_row), player_team, INDEX($C:$C, player_row), current_hole, $B38, flight_number, VALUE(RIGHT(player_flight, LEN(player_flight) - 7)), pair_id, "F" & flight_number & "-" & player_team, pair_row, MATCH(pair_id, $I:$I, 0), is_mixed, INDEX($N:$N, pair_row), mixed_hcp_index, VLOOKUP(current_hole, Course!$A:$G, 7, FALSE), default_hcp_index, VLOOKUP(current_hole, Course!$A:$G, 3, FALSE), hole_hcp_index_to_use, IF(is_mixed, mixed_hcp_index, default_hcp_index), strokes, IF(player_hcp>=hole_hcp_index_to_use, 1, 0) + IF(player_hcp>=(18+hole_hcp_index_to_use), 1, 0), strokes )} -> 0 | G38: =IF($C38=0,"",$C38-F38) -> 5 | H38: {=SUMIFS(Front9_Scores!$D:$D, Front9_Scores!$A:$A, $A38, Front9_Scores!$B:$B, INDEX($B:$B,$AB38), Front9_Scores!$C:$C, $B38)} -> 4 | I38: {=LET(player_hcp,INDEX($E:$E,$AB38),player_tee,INDEX($F:$F,$AB38),current_hole,$B38,hole_hcp_index,XLOOKUP(current_hole,Course!$A:$A,XLOOKUP(player_tee,Course!$D$1:$F$1,Course!$D:$F)),IF(player_hcp>=hole_hcp_index,1,0)+IF(player_hcp>=(18+hole_hcp_index),1,0))} -> 0 | J38: =IF($H38=0,"",$H38-I38) -> 4 | K38: {=LET( player_row, $AB38, player_hcp, INDEX($E:$E, player_row), player_flight, INDEX($A:$A, player_row), player_team, INDEX($C:$C, player_row), current_hole, $B38, flight_number, VALUE(RIGHT(player_flight, LEN(player_flight) - 7)), pair_id, "F" & flight_number & "-" & player_team, pair_row, MATCH(pair_id, $I:$I, 0), is_mixed, INDEX($N:$N, pair_row), mixed_hcp_index, VLOOKUP(current_hole, Course!$A:$G, 7, FALSE), default_hcp_index, VLOOKUP(current_hole, Course!$A:$G, 3, FALSE), hole_hcp_index_to_use, IF(is_mixed, mixed_hcp_index, default_hcp_index), strokes, IF(player_hcp>=hole_hcp_index_to_use, 1, 0) + IF(player_hcp>=(18+hole_hcp_index_to_use), 1, 0), strokes )} -> 0 | L38: =IF($H38=0,"",$H38-K38) -> 4 | M38: {=SUMIFS(Front9_Scores!$D:$D, Front9_Scores!$A:$A, $A38, Front9_Scores!$B:$B, INDEX($B:$B,$AC38), Front9_Scores!$C:$C, $B38)} -> 5 | N38: {=LET(player_hcp,INDEX($E:$E,$AC38),player_tee,INDEX($F:$F,$AC38),current_hole,$B38,hole_hcp_index,XLOOKUP(current_hole,Course!$A:$A,XLOOKUP(player_tee,Course!$D$1:$F$1,Course!$D:$F)),IF(player_hcp>=hole_hcp_index,1,0)+IF(player_hcp>=(18+hole_hcp_index),1,0))} -> 0 | O38: =IF(M38=0,"",M38-N38) -> 5 | P38: {=LET( player_row, $AC38, player_hcp, INDEX($E:$E, player_row), player_flight, INDEX($A:$A, player_row), player_team, INDEX($C:$C, player_row), current_hole, $B38, flight_number, VALUE(RIGHT(player_flight, LEN(player_flight) - 7)), pair_id, "F" & flight_number & "-" & player_team, pair_row, MATCH(pair_id, $I:$I, 0), is_mixed, INDEX($N:$N, pair_row), mixed_hcp_index, VLOOKUP(current_hole, Course!$A:$G, 7, FALSE), default_hcp_index, VLOOKUP(current_hole, Course!$A:$G, 3, FALSE), hole_hcp_index_to_use, IF(is_mixed, mixed_hcp_index, default_hcp_index), strokes, IF(player_hcp>=hole_hcp_index_to_use, 1, 0) + IF(player_hcp>=(18+hole_hcp_index_to_use), 1, 0), strokes )} -> 0 | Q38: =IF($M38=0,"",$M38-P38) -> 5 | R38: {=SUMIFS(Front9_Scores!$D:$D, Front9_Scores!$A:$A, $A38, Front9_Scores!$B:$B, INDEX($B:$B,$AD38), Front9_Scores!$C:$C, $B38)} -> 5 | S38: {=LET(player_hcp,INDEX($E:$E,$AD38),player_tee,INDEX($F:$F,$AD38),current_hole,$B38,hole_hcp_index,XLOOKUP(current_hole,Course!$A:$A,XLOOKUP(player_tee,Course!$D$1:$F$1,Course!$D:$F)),IF(player_hcp>=hole_hcp_index,1,0)+IF(player_hcp>=(18+hole_hcp_index),1,0))} -> 0 | T38: =IF(R38=0,"",R38-S38) -> 5 | U38: {=LET( player_row, $AD38, player_hcp, INDEX($E:$E, player_row), player_flight, INDEX($A:$A, player_row), player_team, INDEX($C:$C, player_row), current_hole, $B38, flight_number, VALUE(RIGHT(player_flight, LEN(player_flight) - 7)), pair_id, "F" & flight_number & "-" & player_team, pair_row, MATCH(pair_id, $I:$I, 0), is_mixed, INDEX($N:$N, pair_row), mixed_hcp_index, VLOOKUP(current_hole, Course!$A:$G, 7, FALSE), default_hcp_index, VLOOKUP(current_hole, Course!$A:$G, 3, FALSE), hole_hcp_index_to_use, IF(is_mixed, mixed_hcp_index, default_hcp_index), strokes, IF(player_hcp>=hole_hcp_index_to_use, 1, 0) + IF(player_hcp>=(18+hole_hcp_index_to_use), 1, 0), strokes )} -> 0 | V38: =IF($R38=0,"",$R38-U38) -> 5 | W38: =IF(COUNT(G38,L38,Q38,V38)<4,"",LET(Red_Best_Ball,MIN(G38,L38),Blue_Best_Ball,MIN(Q38,V38),IF(Red_Best_Ball<Blue_Best_Ball,"Red",IF(Blue_Best_Ball<Red_Best_Ball,"Blue","Tie")))) -> Red | X38: =IF(COUNT(E38,O38)<2,"",IF(E38<O38,"Red",IF(O38<E38,"Blue","Tie"))) -> Tie | Y38: =IF(COUNT(J38,T38)<2,"",IF(J38<T38,"Red",IF(T38<J38,"Blue","Tie"))) -> Red | Z38: =A38 -> Flight_1 | AA38: 4 | AB38: 5 | AC38: 2 | AD38: 3
A39: Flight_1 | B39: 4 | C39: {=SUMIFS(Front9_Scores!$D:$D, Front9_Scores!$A:$A, $A39, Front9_Scores!$B:$B, INDEX($B:$B,$AA39), Front9_Scores!$C:$C, $B39)} -> 4 | D39: {=LET(player_hcp,INDEX($E:$E,$AA39),player_tee,INDEX($F:$F,$AA39),current_hole,$B39,hole_hcp_index,XLOOKUP(current_hole,Course!$A:$A,XLOOKUP(player_tee,Course!$D$1:$F$1,Course!$D:$F)),IF(player_hcp>=hole_hcp_index,1,0)+IF(player_hcp>=(18+hole_hcp_index),1,0))} -> 0 | E39: =IF($C39=0,"",$C39-D39) -> 4 | F39: {=LET( player_row, $AA39, player_hcp, INDEX($E:$E, player_row), player_flight, INDEX($A:$A, player_row), player_team, INDEX($C:$C, player_row), current_hole, $B39, flight_number, VALUE(RIGHT(player_flight, LEN(player_flight) - 7)), pair_id, "F" & flight_number & "-" & player_team, pair_row, MATCH(pair_id, $I:$I, 0), is_mixed, INDEX($N:$N, pair_row), mixed_hcp_index, VLOOKUP(current_hole, Course!$A:$G, 7, FALSE), default_hcp_index, VLOOKUP(current_hole, Course!$A:$G, 3, FALSE), hole_hcp_index_to_use, IF(is_mixed, mixed_hcp_index, default_hcp_index), strokes, IF(player_hcp>=hole_hcp_index_to_use, 1, 0) + IF(player_hcp>=(18+hole_hcp_index_to_use), 1, 0), strokes )} -> 0 | G39: =IF($C39=0,"",$C39-F39) -> 4 | H39: {=SUMIFS(Front9_Scores!$D:$D, Front9_Scores!$A:$A, $A39, Front9_Scores!$B:$B, INDEX($B:$B,$AB39), Front9_Scores!$C:$C, $B39)} -> 5 | I39: {=LET(player_hcp,INDEX($E:$E,$AB39),player_tee,INDEX($F:$F,$AB39),current_hole,$B39,hole_hcp_index,XLOOKUP(current_hole,Course!$A:$A,XLOOKUP(player_tee,Course!$D$1:$F$1,Course!$D:$F)),IF(player_hcp>=hole_hcp_index,1,0)+IF(player_hcp>=(18+hole_hcp_index),1,0))} -> 1 | J39: =IF($H39=0,"",$H39-I39) -> 4 | K39: {=LET( player_row, $AB39, player_hcp, INDEX($E:$E, player_row), player_flight, INDEX($A:$A, player_row), player_team, INDEX($C:$C, player_row), current_hole, $B39, flight_number, VALUE(RIGHT(player_flight, LEN(player_flight) - 7)), pair_id, "F" & flight_number & "-" & player_team, pair_row, MATCH(pair_id, $I:$I, 0), is_mixed, INDEX($N:$N, pair_row), mixed_hcp_index, VLOOKUP(current_hole, Course!$A:$G, 7, FALSE), default_hcp_index, VLOOKUP(current_hole, Course!$A:$G, 3, FALSE), hole_hcp_index_to_use, IF(is_mixed, mixed_hcp_index, default_hcp_index), strokes, IF(player_hcp>=hole_hcp_index_to_use, 1, 0) + IF(player_hcp>=(18+hole_hcp_index_to_use), 1, 0), strokes )} -> 0 | L39: =IF($H39=0,"",$H39-K39) -> 5 | M39: {=SUMIFS(Front9_Scores!$D:$D, Front9_Scores!$A:$A, $A39, Front9_Scores!$B:$B, INDEX($B:$B,$AC39), Front9_Scores!$C:$C, $B39)} -> 4 | N39: {=LET(player_hcp,INDEX($E:$E,$AC39),player_tee,INDEX($F:$F,$AC39),current_hole,$B39,hole_hcp_index,XLOOKUP(current_hole,Course!$A:$A,XLOOKUP(player_tee,Course!$D$1:$F$1,Course!$D:$F)),IF(player_hcp>=hole_hcp_index,1,0)+IF(player_hcp>=(18+hole_hcp_index),1,0))} -> 0 | O39: =IF(M39=0,"",M39-N39) -> 4 | P39: {=LET( player_row, $AC39, player_hcp, INDEX($E:$E, player_row), player_flight, INDEX($A:$A, player_row), player_team, INDEX($C:$C, player_row), current_hole, $B39, flight_number, VALUE(RIGHT(player_flight, LEN(player_flight) - 7)), pair_id, "F" & flight_number & "-" & player_team, pair_row, MATCH(pair_id, $I:$I, 0), is_mixed, INDEX($N:$N, pair_row), mixed_hcp_index, VLOOKUP(current_hole, Course!$A:$G, 7, FALSE), default_hcp_index, VLOOKUP(current_hole, Course!$A:$G, 3, FALSE), hole_hcp_index_to_use, IF(is_mixed, mixed_hcp_index, default_hcp_index), strokes, IF(player_hcp>=hole_hcp_index_to_use, 1, 0) + IF(player_hcp>=(18+hole_hcp_index_to_use), 1, 0), strokes )} -> 0 | Q39: =IF($M39=0,"",$M39-P39) -> 4 | R39: {=SUMIFS(Front9_Scores!$D:$D, Front9_Scores!$A:$A, $A39, Front9_Scores!$B:$B, INDEX($B:$B,$AD39), Front9_Scores!$C:$C, $B39)} -> 5 | S39: {=LET(player_hcp,INDEX($E:$E,$AD39),player_tee,INDEX($F:$F,$AD39),current_hole,$B39,hole_hcp_index,XLOOKUP(current_hole,Course!$A:$A,XLOOKUP(player_tee,Course!$D$1:$F$1,Course!$D:$F)),IF(player_hcp>=hole_hcp_index,1,0)+IF(player_hcp>=(18+hole_hcp_index),1,0))} -> 1 | T39: =IF(R39=0,"",R39-S39) -> 4 | U39: {=LET( player_row, $AD39, player_hcp, INDEX($E:$E, player_row), player_flight, INDEX($A:$A, player_row), player_team, INDEX($C:$C, player_row), current_hole, $B39, flight_number, VALUE(RIGHT(player_flight, LEN(player_flight) - 7)), pair_id, "F" & flight_number & "-" & player_team, pair_row, MATCH(pair_id, $I:$I, 0), is_mixed, INDEX($N:$N, pair_row), mixed_hcp_index, VLOOKUP(current_hole, Course!$A:$G, 7, FALSE), default_hcp_index, VLOOKUP(current_hole, Course!$A:$G, 3, FALSE), hole_hcp_index_to_use, IF(is_mixed, mixed_hcp_index, default_hcp_index), strokes, IF(player_hcp>=hole_hcp_index_to_use, 1, 0) + IF(player_hcp>=(18+hole_hcp_index_to_use), 1, 0), strokes )} -> 1 | V39: =IF($R39=0,"",$R39-U39) -> 4 | W39: =IF(COUNT(G39,L39,Q39,V39)<4,"",LET(Red_Best_Ball,MIN(G39,L39),Blue_Best_Ball,MIN(Q39,V39),IF(Red_Best_Ball<Blue_Best_Ball,"Red",IF(Blue_Best_Ball<Red_Best_Ball,"Blue","Tie")))) -> Tie | X39: =IF(COUNT(E39,O39)<2,"",IF(E39<O39,"Red",IF(O39<E39,"Blue","Tie"))) -> Tie | Y39: =IF(COUNT(J39,T39)<2,"",IF(J39<T39,"Red",IF(T39<J39,"Blue","Tie"))) -> Tie | Z39: =A39 -> Flight_1 | AA39: 4 | AB39: 5 | AC39: 2 | AD39: 3
A40: Flight_1 | B40: 5 | C40: {=SUMIFS(Front9_Scores!$D:$D, Front9_Scores!$A:$A, $A40, Front9_Scores!$B:$B, INDEX($B:$B,$AA40), Front9_Scores!$C:$C, $B40)} -> 2 | D40: {=LET(player_hcp,INDEX($E:$E,$AA40),player_tee,INDEX($F:$F,$AA40),current_hole,$B40,hole_hcp_index,XLOOKUP(current_hole,Course!$A:$A,XLOOKUP(player_tee,Course!$D$1:$F$1,Course!$D:$F)),IF(player_hcp>=hole_hcp_index,1,0)+IF(player_hcp>=(18+hole_hcp_index),1,0))} -> 1 | E40: =IF($C40=0,"",$C40-D40) -> 1 | F40: {=LET( player_row, $AA40, player_hcp, INDEX($E:$E, player_row), player_flight, INDEX($A:$A, player_row), player_team, INDEX($C:$C, player_row), current_hole, $B40, flight_number, VALUE(RIGHT(player_flight, LEN(player_flight) - 7)), pair_id, "F" & flight_number & "-" & player_team, pair_row, MATCH(pair_id, $I:$I, 0), is_mixed, INDEX($N:$N, pair_row), mixed_hcp_index, VLOOKUP(current_hole, Course!$A:$G, 7, FALSE), default_hcp_index, VLOOKUP(current_hole, Course!$A:$G, 3, FALSE), hole_hcp_index_to_use, IF(is_mixed, mixed_hcp_index, default_hcp_index), strokes, IF(player_hcp>=hole_hcp_index_to_use, 1, 0) + IF(player_hcp>=(18+hole_hcp_index_to_use), 1, 0), strokes )} -> 1 | G40: =IF($C40=0,"",$C40-F40) -> 1 | H40: {=SUMIFS(Front9_Scores!$D:$D, Front9_Scores!$A:$A, $A40, Front9_Scores!$B:$B, INDEX($B:$B,$AB40), Front9_Scores!$C:$C, $B40)} -> 4 | I40: {=LET(player_hcp,INDEX($E:$E,$AB40),player_tee,INDEX($F:$F,$AB40),current_hole,$B40,hole_hcp_index,XLOOKUP(current_hole,Course!$A:$A,XLOOKUP(player_tee,Course!$D$1:$F$1,Course!$D:$F)),IF(player_hcp>=hole_hcp_index,1,0)+IF(player_hcp>=(18+hole_hcp_index),1,0))} -> 1 | J40: =IF($H40=0,"",$H40-I40) -> 3 | K40: {=LET( player_row, $AB40, player_hcp, INDEX($E:$E, player_row), player_flight, INDEX($A:$A, player_row), player_team, INDEX($C:$C, player_row), current_hole, $B40, flight_number, VALUE(RIGHT(player_flight, LEN(player_flight) - 7)), pair_id, "F" & flight_number & "-" & player_team, pair_row, MATCH(pair_id, $I:$I, 0), is_mixed, INDEX($N:$N, pair_row), mixed_hcp_index, VLOOKUP(current_hole, Course!$A:$G, 7, FALSE), default_hcp_index, VLOOKUP(current_hole, Course!$A:$G, 3, FALSE), hole_hcp_index_to_use, IF(is_mixed, mixed_hcp_index, default_hcp_index), strokes, IF(player_hcp>=hole_hcp_index_to_use, 1, 0) + IF(player_hcp>=(18+hole_hcp_index_to_use), 1, 0), strokes )} -> 1 | L40: =IF($H40=0,"",$H40-K40) -> 3 | M40: {=SUMIFS(Front9_Scores!$D:$D, Front9_Scores!$A:$A, $A40, Front9_Scores!$B:$B, INDEX($B:$B,$AC40), Front9_Scores!$C:$C, $B40)} -> 3 | N40: {=LET(player_hcp,INDEX($E:$E,$AC40),player_tee,INDEX($F:$F,$AC40),current_hole,$B40,hole_hcp_index,XLOOKUP(current_hole,Course!$A:$A,XLOOKUP(player_tee,Course!$D$1:$F$1,Course!$D:$F)),IF(player_hcp>=hole_hcp_index,1,0)+IF(player_hcp>=(18+hole_hcp_index),1,0))} -> 1 | O40: =IF(M40=0,"",M40-N40) -> 2 | P40: {=LET( player_row, $AC40, player_hcp, INDEX($E:$E, player_row), player_flight, INDEX($A:$A, player_row), player_team, INDEX($C:$C, player_row), current_hole, $B40, flight_number, VALUE(RIGHT(player_flight, LEN(player_flight) - 7)), pair_id, "F" & flight_number & "-" & player_team, pair_row, MATCH(pair_id, $I:$I, 0), is_mixed, INDEX($N:$N, pair_row), mixed_hcp_index, VLOOKUP(current_hole, Course!$A:$G, 7, FALSE), default_hcp_index, VLOOKUP(current_hole, Course!$A:$G, 3, FALSE), hole_hcp_index_to_use, IF(is_mixed, mixed_hcp_index, default_hcp_index), strokes, IF(player_hcp>=hole_hcp_index_to_use, 1, 0) + IF(player_hcp>=(18+hole_hcp_index_to_use), 1, 0), strokes )} -> 1 | Q40: =IF($M40=0,"",$M40-P40) -> 2 | R40: {=SUMIFS(Front9_Scores!$D:$D, Front9_Scores!$A:$A, $A40, Front9_Scores!$B:$B, INDEX($B:$B,$AD40), Front9_Scores!$C:$C, $B40)} -> 6 | S40: {=LET(player_hcp,INDEX($E:$E,$AD40),player_tee,INDEX($F:$F,$AD40),current_hole,$B40,hole_hcp_index,XLOOKUP(current_hole,Course!$A:$A,XLOOKUP(player_tee,Course!$D$1:$F$1,Course!$D:$F)),IF(player_hcp>=hole_hcp_index,1,0)+IF(player_hcp>=(18+hole_hcp_index),1,0))} -> 1 | T40: =IF(R40=0,"",R40-S40) -> 5 | U40: {=LET( player_row, $AD40, player_hcp, INDEX($E:$E, player_row), player_flight, INDEX($A:$A, player_row), player_team, INDEX($C:$C, player_row), current_hole, $B40, flight_number, VALUE(RIGHT(player_flight, LEN(player_flight) - 7)), pair_id, "F" & flight_number & "-" & player_team, pair_row, MATCH(pair_id, $I:$I, 0), is_mixed, INDEX($N:$N, pair_row), mixed_hcp_index, VLOOKUP(current_hole, Course!$A:$G, 7, FALSE), default_hcp_index, VLOOKUP(current_hole, Course!$A:$G, 3, FALSE), hole_hcp_index_to_use, IF(is_mixed, mixed_hcp_index, default_hcp_index), strokes, IF(player_hcp>=hole_hcp_index_to_use, 1, 0) + IF(player_hcp>=(18+hole_hcp_index_to_use), 1, 0), strokes )} -> 1 | V40: =IF($R40=0,"",$R40-U40) -> 5 | W40: =IF(COUNT(G40,L40,Q40,V40)<4,"",LET(Red_Best_Ball,MIN(G40,L40),Blue_Best_Ball,MIN(Q40,V40),IF(Red_Best_Ball<Blue_Best_Ball,"Red",IF(Blue_Best_Ball<Red_Best_Ball,"Blue","Tie")))) -> Red | X40: =IF(COUNT(E40,O40)<2,"",IF(E40<O40,"Red",IF(O40<E40,"Blue","Tie"))) -> Red | Y40: =IF(COUNT(J40,T40)<2,"",IF(J40<T40,"Red",IF(T40<J40,"Blue","Tie"))) -> Red | Z40: =A40 -> Flight_1 | AA40: 4 | AB40: 5 | AC40: 2 | AD40: 3
A41: Flight_1 | B41: 6 | C41: {=SUMIFS(Front9_Scores!$D:$D, Front9_Scores!$A:$A, $A41, Front9_Scores!$B:$B, INDEX($B:$B,$AA41), Front9_Scores!$C:$C, $B41)} -> 6 | D41: {=LET(player_hcp,INDEX($E:$E,$AA41),player_tee,INDEX($F:$F,$AA41),current_hole,$B41,hole_hcp_index,XLOOKUP(current_hole,Course!$A:$A,XLOOKUP(player_tee,Course!$D$1:$F$1,Course!$D:$F)),IF(player_hcp>=hole_hcp_index,1,0)+IF(player_hcp>=(18+hole_hcp_index),1,0))} -> 1 | E41: =IF($C41=0,"",$C41-D41) -> 5 | F41: {=LET( player_row, $AA41, player_hcp, INDEX($E:$E, player_row), player_flight, INDEX($A:$A, player_row), player_team, INDEX($C:$C, player_row), current_hole, $B41, flight_number, VALUE(RIGHT(player_flight, LEN(player_flight) - 7)), pair_id, "F" & flight_number & "-" & player_team, pair_row, MATCH(pair_id, $I:$I, 0), is_mixed, INDEX($N:$N, pair_row), mixed_hcp_index, VLOOKUP(current_hole, Course!$A:$G, 7, FALSE), default_hcp_index, VLOOKUP(current_hole, Course!$A:$G, 3, FALSE), hole_hcp_index_to_use, IF(is_mixed, mixed_hcp_index, default_hcp_index), strokes, IF(player_hcp>=hole_hcp_index_to_use, 1, 0) + IF(player_hcp>=(18+hole_hcp_index_to_use), 1, 0), strokes )} -> 0 | G41: =IF($C41=0,"",$C41-F41) -> 6 | H41: {=SUMIFS(Front9_Scores!$D:$D, Front9_Scores!$A:$A, $A41, Front9_Scores!$B:$B, INDEX($B:$B,$AB41), Front9_Scores!$C:$C, $B41)} -> 5 | I41: {=LET(player_hcp,INDEX($E:$E,$AB41),player_tee,INDEX($F:$F,$AB41),current_hole,$B41,hole_hcp_index,XLOOKUP(current_hole,Course!$A:$A,XLOOKUP(player_tee,Course!$D$1:$F$1,Course!$D:$F)),IF(player_hcp>=hole_hcp_index,1,0)+IF(player_hcp>=(18+hole_hcp_index),1,0))} -> 0 | J41: =IF($H41=0,"",$H41-I41) -> 5 | K41: {=LET( player_row, $AB41, player_hcp, INDEX($E:$E, player_row), player_flight, INDEX($A:$A, player_row), player_team, INDEX($C:$C, player_row), current_hole, $B41, flight_number, VALUE(RIGHT(player_flight, LEN(player_flight) - 7)), pair_id, "F" & flight_number & "-" & player_team, pair_row, MATCH(pair_id, $I:$I, 0), is_mixed, INDEX($N:$N, pair_row), mixed_hcp_index, VLOOKUP(current_hole, Course!$A:$G, 7, FALSE), default_hcp_index, VLOOKUP(current_hole, Course!$A:$G, 3, FALSE), hole_hcp_index_to_use, IF(is_mixed, mixed_hcp_index, default_hcp_index), strokes, IF(player_hcp>=hole_hcp_index_to_use, 1, 0) + IF(player_hcp>=(18+hole_hcp_index_to_use), 1, 0), strokes )} -> 1 | L41: =IF($H41=0,"",$H41-K41) -> 4 | M41: {=SUMIFS(Front9_Scores!$D:$D, Front9_Scores!$A:$A, $A41, Front9_Scores!$B:$B, INDEX($B:$B,$AC41), Front9_Scores!$C:$C, $B41)} -> 5 | N41: {=LET(player_hcp,INDEX($E:$E,$AC41),player_tee,INDEX($F:$F,$AC41),current_hole,$B41,hole_hcp_index,XLOOKUP(current_hole,Course!$A:$A,XLOOKUP(player_tee,Course!$D$1:$F$1,Course!$D:$F)),IF(player_hcp>=hole_hcp_index,1,0)+IF(player_hcp>=(18+hole_hcp_index),1,0))} -> 1 | O41: =IF(M41=0,"",M41-N41) -> 4 | P41: {=LET( player_row, $AC41, player_hcp, INDEX($E:$E, player_row), player_flight, INDEX($A:$A, player_row), player_team, INDEX($C:$C, player_row), current_hole, $B41, flight_number, VALUE(RIGHT(player_flight, LEN(player_flight) - 7)), pair_id, "F" & flight_number & "-" & player_team, pair_row, MATCH(pair_id, $I:$I, 0), is_mixed, INDEX($N:$N, pair_row), mixed_hcp_index, VLOOKUP(current_hole, Course!$A:$G, 7, FALSE), default_hcp_index, VLOOKUP(current_hole, Course!$A:$G, 3, FALSE), hole_hcp_index_to_use, IF(is_mixed, mixed_hcp_index, default_hcp_index), strokes, IF(player_hcp>=hole_hcp_index_to_use, 1, 0) + IF(player_hcp>=(18+hole_hcp_index_to_use), 1, 0), strokes )} -> 1 | Q41: =IF($M41=0,"",$M41-P41) -> 4 | R41: {=SUMIFS(Front9_Scores!$D:$D, Front9_Scores!$A:$A, $A41, Front9_Scores!$B:$B, INDEX($B:$B,$AD41), Front9_Scores!$C:$C, $B41)} -> 4 | S41: {=LET(player_hcp,INDEX($E:$E,$AD41),player_tee,INDEX($F:$F,$AD41),current_hole,$B41,hole_hcp_index,XLOOKUP(current_hole,Course!$A:$A,XLOOKUP(player_tee,Course!$D$1:$F$1,Course!$D:$F)),IF(player_hcp>=hole_hcp_index,1,0)+IF(player_hcp>=(18+hole_hcp_index),1,0))} -> 1 | T41: =IF(R41=0,"",R41-S41) -> 3 | U41: {=LET( player_row, $AD41, player_hcp, INDEX($E:$E, player_row), player_flight, INDEX($A:$A, player_row), player_team, INDEX($C:$C, player_row), current_hole, $B41, flight_number, VALUE(RIGHT(player_flight, LEN(player_flight) - 7)), pair_id, "F" & flight_number & "-" & player_team, pair_row, MATCH(pair_id, $I:$I, 0), is_mixed, INDEX($N:$N, pair_row), mixed_hcp_index, VLOOKUP(current_hole, Course!$A:$G, 7, FALSE), default_hcp_index, VLOOKUP(current_hole, Course!$A:$G, 3, FALSE), hole_hcp_index_to_use, IF(is_mixed, mixed_hcp_index, default_hcp_index), strokes, IF(player_hcp>=hole_hcp_index_to_use, 1, 0) + IF(player_hcp>=(18+hole_hcp_index_to_use), 1, 0), strokes )} -> 1 | V41: =IF($R41=0,"",$R41-U41) -> 3 | W41: =IF(COUNT(G41,L41,Q41,V41)<4,"",LET(Red_Best_Ball,MIN(G41,L41),Blue_Best_Ball,MIN(Q41,V41),IF(Red_Best_Ball<Blue_Best_Ball,"Red",IF(Blue_Best_Ball<Red_Best_Ball,"Blue","Tie")))) -> Blue | X41: =IF(COUNT(E41,O41)<2,"",IF(E41<O41,"Red",IF(O41<E41,"Blue","Tie"))) -> Blue | Y41: =IF(COUNT(J41,T41)<2,"",IF(J41<T41,"Red",IF(T41<J41,"Blue","Tie"))) -> Blue | Z41: =A41 -> Flight_1 | AA41: 4 | AB41: 5 | AC41: 2 | AD41: 3
...

Sheet Front9_Data
A1: <div | B1: Hole | C1: P1_Red-Gross | D1: P1-Red-Strokes_IND | E1: P1-Red-Net_IND | F1: P1-Red-Strokes_FB | G1: P1-Red-Net_FB | H1: P2-Red-Gross | I1: P2-Red-Strokes_IND | J1: P2-Red-Net_IND | K1: P2-Red-Strokes_FB | L1: P2-Red-Net_FB | M1: P1-Blue-Gross | N1: P1-Blue-Strokes_IND | O1: P1-Blue-Net_IND | P1: P1-Blue-Strokes_FB | Q1: P1-Blue-Net_FB | R1: P2-Blue-Gross | S1: P2-Blue-Strokes_IND | T1: P2-Blue-Net_IND | U1: P2-Blue-Strokes_FB | V1: P2-Blue-Net_FB | W1: FB-Winner | X1: I1-Winner | Y1: I2-Winner | Z1: Match_ID | AA1: P1_Red_Name | AB1: P2_Red_Name | AC1: P1_Blue_Name | AD1: P2_Blue_Name | AE1: Hole_Value_FB | AF1: Running_Sum_FB | AG1: Running_Status_FB | AH1: Hole_Value_I1 | AI1: Hole_Value_I2 | AJ1: Running_Sum_I1 | AK1: Running_Status_I1 | AL1: Running_Status_I1_Color | AM1: Running_Sum_I2 | AN1: Running_Status_I2 | AO1: Red_Min_Net_FB | AP1: Blue_Min_Net_FB
A2: {=Calc_Engine!A36:A44} -> Flight_1 | B2: {=Calc_Engine!B36:B44} -> 1 | C2: {=Calc_Engine!C36:C44} -> 6 | F2: {=Calc_Engine!F36:F44} -> 1 | G2: {=Calc_Engine!G36:G44} -> 5 | H2: {=Calc_Engine!H36:H44} -> 7 | K2: {=Calc_Engine!K36:K44} -> 1 | L2: {=Calc_Engine!L36:L44} -> 6 | M2: {=Calc_Engine!M36:M44} -> 5 | P2: {=Calc_Engine!P36:P44} -> 1 | Q2: {=Calc_Engine!Q36:Q44} -> 4 | R2: {=Calc_Engine!R36:R44} -> 5 | U2: {=Calc_Engine!U36:U44} -> 1 | V2: {=Calc_Engine!V36:V44} -> 4 | W2: {=Calc_Engine!W36:W44} -> Blue | Z2: Flight_1_Fourball | AA2: =IFERROR(__xludf.DUMMYFUNCTION("IF(A2="""","""",INDEX(FILTER(Roster!$A:$A,(Roster!$C:$C=A2)*(Roster!$F:$F=3)),1))"),"Fito") -> Fito | AB2: =IFERROR(__xludf.DUMMYFUNCTION("IF(A2="""","""",INDEX(FILTER(Roster!$A:$A,(Roster!$C:$C=A2)*(Roster!$F:$F=4)),1))"),"Adri Mejia") -> Adri Mejia | AC2: =IFERROR(__xludf.DUMMYFUNCTION("IF(A2="""","""",INDEX(FILTER(Roster!$A:$A,(Roster!$C:$C=A2)*(Roster!$F:$F=1)),1))"),"Fercho") -> Fercho | AD2: =IFERROR(__xludf.DUMMYFUNCTION("IF(A2="""","""",INDEX(FILTER(Roster!$A:$A,(Roster!$C:$C=A2)*(Roster!$F:$F=2)),1))"),"Gaitan") -> Gaitan | AE2: {=IF(A2:A217="", "", IF(W2:W217="Red", 1, IF(W2:W217="Blue", -1, 0)))} -> -1 | AF2: {=MAP(A2:A217, B2:B217, Z2:Z217, LAMBDA(a_val, b_val, z_val, IF(a_val="", "", SUMIFS(AE$2:AE217, Z$2:Z217, z_val, B$2:B217, "<=" & b_val))))} -> -1 | AG2: {=IF(A2:A217="", "", IF(AF2:AF217=0, "A/S", ABS(AF2:AF217) & " UP"))} -> 1 UP | AH2: {=IF(A2:A217="", "", IF(X2:X217="Red", 1, IF(X2:X217="Blue", -1, 0)))} -> 0 | AI2: {=IF(A2:A217="", "", IF(Y2:Y217="Red", 1, IF(Y2:Y217="Blue", -1, 0)))} -> 0 | AJ2: {=MAP(A2:A217, B2:B217, Z2:Z217, LAMBDA(a_val, b_val, z_val, IF(a_val="", "", SUMIFS(AH$2:AH217, Z$2:Z217, z_val, B$2:B217, "<=" & b_val))))} -> 0 | AK2: {=IF(A2:A217="", "", IF(AJ2:AJ217=0, "A/S", ABS(AJ2:AJ217) & " UP"))} -> A/S | AL2: {=IF(A2:A217="", "", IF(AJ2:AJ217>0, "#D32F2F", IF(AJ2:AJ217<0, "#1976D2", "#616161")) )} -> #616161 | AM2: {=MAP(A2:A217, B2:B217, Z2:Z217, LAMBDA(a_val, b_val, z_val, IF(a_val="", "", SUMIFS(AI$2:AI217, Z$2:Z217, z_val, B$2:B217, "<=" & b_val))))} -> 0 | AN2: {=IF(A2:A217="", "", IF(AM2:AM217=0, "A/S", ABS(AM2:AM217) & " UP"))} -> A/S | AO2: =min(G2,L2) -> 5 | AP2: =min(Q2,V2) -> 4
A3: Flight_1 | B3: 2 | C3: 5 | F3: 1 | G3: 4 | H3: 6 | K3: 1 | L3: 5 | M3: 6 | P3: 1 | Q3: 5 | R3: 6 | U3: 1 | V3: 5 | W3: Red | Z3: Flight_1_Fourball | AA3: =IFERROR(__xludf.DUMMYFUNCTION("IF(A3="""","""",INDEX(FILTER(Roster!$A:$A,(Roster!$C:$C=A3)*(Roster!$F:$F=3)),1))"),"Fito") -> Fito | AB3: =IFERROR(__xludf.DUMMYFUNCTION("IF(A3="""","""",INDEX(FILTER(Roster!$A:$A,(Roster!$C:$C=A3)*(Roster!$F:$F=4)),1))"),"Adri Mejia") -> Adri Mejia | AC3: =IFERROR(__xludf.DUMMYFUNCTION("IF(A3="""","""",INDEX(FILTER(Roster!$A:$A,(Roster!$C:$C=A3)*(Roster!$F:$F=1)),1))"),"Fercho") -> Fercho | AD3: =IFERROR(__xludf.DUMMYFUNCTION("IF(A3="""","""",INDEX(FILTER(Roster!$A:$A,(Roster!$C:$C=A3)*(Roster!$F:$F=2)),1))"),"Gaitan") -> Gaitan | AE3: 1 | AF3: 0 | AG3: A/S | AH3: 0 | AI3: 0 | AJ3: 0 | AK3: A/S | AL3: #616161 | AM3: 0 | AN3: A/S | AO3: =min(G3,L3) -> 4 | AP3: =min(Q3,V3) -> 5
A4: Flight_1 | B4: 3 | C4: 5 | F4: 0 | G4: 5 | H4: 4 | K4: 0 | L4: 4 | M4: 5 | P4: 0 | Q4: 5 | R4: 5 | U4: 0 | V4: 5 | W4: Red | Z4: Flight_1_Fourball | AA4: =IFERROR(__xludf.DUMMYFUNCTION("IF(A4="""","""",INDEX(FILTER(Roster!$A:$A,(Roster!$C:$C=A4)*(Roster!$F:$F=3)),1))"),"Fito") -> Fito | AB4: =IFERROR(__xludf.DUMMYFUNCTION("IF(A4="""","""",INDEX(FILTER(Roster!$A:$A,(Roster!$C:$C=A4)*(Roster!$F:$F=4)),1))"),"Adri Mejia") -> Adri Mejia | AC4: =IFERROR(__xludf.DUMMYFUNCTION("IF(A4="""","""",INDEX(FILTER(Roster!$A:$A,(Roster!$C:$C=A4)*(Roster!$F:$F=1)),1))"),"Fercho") -> Fercho | AD4: =IFERROR(__xludf.DUMMYFUNCTION("IF(A4="""","""",INDEX(FILTER(Roster!$A:$A,(Roster!$C:$C=A4)*(Roster!$F:$F=2)),1))"),"Gaitan") -> Gaitan | AE4: 1 | AF4: 1 | AG4: 1 UP | AH4: 0 | AI4: 0 | AJ4: 0 | AK4: A/S | AL4: #616161 | AM4: 0 | AN4: A/S | AO4: =min(G4,L4) -> 4 | AP4: =min(Q4,V4) -> 5
A5: Flight_1 | B5: 4 | C5: 4 | F5: 0 | G5: 4 | H5: 5 | K5: 0 | L5: 5 | M5: 4 | P5: 0 | Q5: 4 | R5: 5 | U5: 1 | V5: 4 | W5: Tie | Z5: Flight_1_Fourball | AA5: =IFERROR(__xludf.DUMMYFUNCTION("IF(A5="""","""",INDEX(FILTER(Roster!$A:$A,(Roster!$C:$C=A5)*(Roster!$F:$F=3)),1))"),"Fito") -> Fito | AB5: =IFERROR(__xludf.DUMMYFUNCTION("IF(A5="""","""",INDEX(FILTER(Roster!$A:$A,(Roster!$C:$C=A5)*(Roster!$F:$F=4)),1))"),"Adri Mejia") -> Adri Mejia | AC5: =IFERROR(__xludf.DUMMYFUNCTION("IF(A5="""","""",INDEX(FILTER(Roster!$A:$A,(Roster!$C:$C=A5)*(Roster!$F:$F=1)),1))"),"Fercho") -> Fercho | AD5: =IFERROR(__xludf.DUMMYFUNCTION("IF(A5="""","""",INDEX(FILTER(Roster!$A:$A,(Roster!$C:$C=A5)*(Roster!$F:$F=2)),1))"),"Gaitan") -> Gaitan | AE5: 0 | AF5: 1 | AG5: 1 UP | AH5: 0 | AI5: 0 | AJ5: 0 | AK5: A/S | AL5: #616161 | AM5: 0 | AN5: A/S | AO5: =min(G5,L5) -> 4 | AP5: =min(Q5,V5) -> 4
A6: Flight_1 | B6: 5 | C6: 2 | F6: 1 | G6: 1 | H6: 4 | K6: 1 | L6: 3 | M6: 3 | P6: 1 | Q6: 2 | R6: 6 | U6: 1 | V6: 5 | W6: Red | Z6: Flight_1_Fourball | AA6: =IFERROR(__xludf.DUMMYFUNCTION("IF(A6="""","""",INDEX(FILTER(Roster!$A:$A,(Roster!$C:$C=A6)*(Roster!$F:$F=3)),1))"),"Fito") -> Fito | AB6: =IFERROR(__xludf.DUMMYFUNCTION("IF(A6="""","""",INDEX(FILTER(Roster!$A:$A,(Roster!$C:$C=A6)*(Roster!$F:$F=4)),1))"),"Adri Mejia") -> Adri Mejia | AC6: =IFERROR(__xludf.DUMMYFUNCTION("IF(A6="""","""",INDEX(FILTER(Roster!$A:$A,(Roster!$C:$C=A6)*(Roster!$F:$F=1)),1))"),"Fercho") -> Fercho | AD6: =IFERROR(__xludf.DUMMYFUNCTION("IF(A6="""","""",INDEX(FILTER(Roster!$A:$A,(Roster!$C:$C=A6)*(Roster!$F:$F=2)),1))"),"Gaitan") -> Gaitan | AE6: 1 | AF6: 2 | AG6: 2 UP | AH6: 0 | AI6: 0 | AJ6: 0 | AK6: A/S | AL6: #616161 | AM6: 0 | AN6: A/S | AO6: =min(G6,L6) -> 1 | AP6: =min(Q6,V6) -> 2
A7: Flight_1 | B7: 6 | C7: 6 | F7: 0 | G7: 6 | H7: 5 | K7: 1 | L7: 4 | M7: 5 | P7: 1 | Q7: 4 | R7: 4 | U7: 1 | V7: 3 | W7: Blue | Z7: Flight_1_Fourball | AA7: =IFERROR(__xludf.DUMMYFUNCTION("IF(A7="""","""",INDEX(FILTER(Roster!$A:$A,(Roster!$C:$C=A7)*(Roster!$F:$F=3)),1))"),"Fito") -> Fito | AB7: =IFERROR(__xludf.DUMMYFUNCTION("IF(A7="""","""",INDEX(FILTER(Roster!$A:$A,(Roster!$C:$C=A7)*(Roster!$F:$F=4)),1))"),"Adri Mejia") -> Adri Mejia | AC7: =IFERROR(__xludf.DUMMYFUNCTION("IF(A7="""","""",INDEX(FILTER(Roster!$A:$A,(Roster!$C:$C=A7)*(Roster!$F:$F=1)),1))"),"Fercho") -> Fercho | AD7: =IFERROR(__xludf.DUMMYFUNCTION("IF(A7="""","""",INDEX(FILTER(Roster!$A:$A,(Roster!$C:$C=A7)*(Roster!$F:$F=2)),1))"),"Gaitan") -> Gaitan | AE7: -1 | AF7: 1 | AG7: 1 UP | AH7: 0 | AI7: 0 | AJ7: 0 | AK7: A/S | AL7: #616161 | AM7: 0 | AN7: A/S | AO7: =min(G7,L7) -> 4 | AP7: =min(Q7,V7) -> 3
A8: Flight_1 | B8: 7 | C8: 2 | F8: 0 | G8: 2 | H8: 3 | K8: 0 | L8: 3 | M8: 3 | P8: 0 | Q8: 3 | R8: 3 | U8: 1 | V8: 2 | W8: Tie | Z8: Flight_1_Fourball | AA8: =IFERROR(__xludf.DUMMYFUNCTION("IF(A8="""","""",INDEX(FILTER(Roster!$A:$A,(Roster!$C:$C=A8)*(Roster!$F:$F=3)),1))"),"Fito") -> Fito | AB8: =IFERROR(__xludf.DUMMYFUNCTION("IF(A8="""","""",INDEX(FILTER(Roster!$A:$A,(Roster!$C:$C=A8)*(Roster!$F:$F=4)),1))"),"Adri Mejia") -> Adri Mejia | AC8: =IFERROR(__xludf.DUMMYFUNCTION("IF(A8="""","""",INDEX(FILTER(Roster!$A:$A,(Roster!$C:$C=A8)*(Roster!$F:$F=1)),1))"),"Fercho") -> Fercho | AD8: =IFERROR(__xludf.DUMMYFUNCTION("IF(A8="""","""",INDEX(FILTER(Roster!$A:$A,(Roster!$C:$C=A8)*(Roster!$F:$F=2)),1))"),"Gaitan") -> Gaitan | AE8: 0 | AF8: 1 | AG8: 1 UP | AH8: 0 | AI8: 0 | AJ8: 0 | AK8: A/S | AL8: #616161 | AM8: 0 | AN8: A/S | AO8: =min(G8,L8) -> 2 | AP8: =min(Q8,V8) -> 2
A9: Flight_1 | B9: 8 | C9: 5 | F9: 1 | G9: 4 | H9: 7 | K9: 1 | L9: 6 | M9: 7 | P9: 1 | Q9: 6 | R9: 6 | U9: 1 | V9: 5 | W9: Red | Z9: Flight_1_Fourball | AA9: =IFERROR(__xludf.DUMMYFUNCTION("IF(A9="""","""",INDEX(FILTER(Roster!$A:$A,(Roster!$C:$C=A9)*(Roster!$F:$F=3)),1))"),"Fito") -> Fito | AB9: =IFERROR(__xludf.DUMMYFUNCTION("IF(A9="""","""",INDEX(FILTER(Roster!$A:$A,(Roster!$C:$C=A9)*(Roster!$F:$F=4)),1))"),"Adri Mejia") -> Adri Mejia | AC9: =IFERROR(__xludf.DUMMYFUNCTION("IF(A9="""","""",INDEX(FILTER(Roster!$A:$A,(Roster!$C:$C=A9)*(Roster!$F:$F=1)),1))"),"Fercho") -> Fercho | AD9: =IFERROR(__xludf.DUMMYFUNCTION("IF(A9="""","""",INDEX(FILTER(Roster!$A:$A,(Roster!$C:$C=A9)*(Roster!$F:$F=2)),1))"),"Gaitan") -> Gaitan | AE9: 1 | AF9: 2 | AG9: 2 UP | AH9: 0 | AI9: 0 | AJ9: 0 | AK9: A/S | AL9: #616161 | AM9: 0 | AN9: A/S | AO9: =min(G9,L9) -> 4 | AP9: =min(Q9,V9) -> 5
